Workbook
Name NativeTimeline_OrderDate: #N/A
Name Slicer_Category: #N/A
Name Slicer_Country: #N/A
Name Slicer_PaymentMethod: #N/A
Name Slicer_Status: #N/A

Sheet uncleandData
A1: OrderID | B1: CustomerName | C1: Email | D1: Phone | E1: Country | F1: OrderDate | G1: Product | H1: Category | I1: Quantity | J1: UnitPrice | K1: TotalAmount | L1: PaymentMethod | M1: Status
A2: 1052 | B2: Daniel Mahmoud | C2: daniel.mahmoud@gmail.com | D2: 225 831 323 | E2: egypt | F2: 07/21/2024 | G2: Yoga Mat | H2: Sportswear | I2: 10 | J2: 18 | K2: 180 | L2: cash | M2: cancelled
A3: 1058 | B3: Noah Johnson | C3: noah.johnson@hotmail.com | D3: (409) 749-930 | E3: uae | F3: 01-Jun-23 | G3: Desk Lamp | H3: furniture | I3: 2 | J3: 15 | K3: 30 | L3: Debit Card | M3: Shipped
A4: 1023 | B4: Daniel Walker | C4: DANIEL.WALKER@OUTLOOK.COM | D4: +20 936-183-242 | E4: United Arab Emirates | F4: 01-Sep-24 | G4: Sunglasses | H4: Accessories | I4: 8 | J4: 22 | K4: 176 | L4: credit card | M4: Completed
A5: 1019 | B5: Emma Abdallah | C5: emma.abdallah@outlook.com | D5: (531) 473-799 | E5: Saudi Arabia | F5: May 21, 2024 | G5: Office Chair | H5: Furniture | I5: 5 | J5: 90 | L5: Credit_Card | M5: completed
A6: 1044 | B6: mia el-sayed | C6: miael-sayed@gmail.com | D6: +20 805-929-622 | E6: U.K. | F6: 2024-03-24 | G6: Ceramic Mug | H6: Kitchenware | I6: 8 | J6: 6 | K6: 48 | L6: Cash | M6: Pending
A7: 1032 | B7: HASSAN SMITH | C7: hassan.smith@yahoo.com | D7: +20 461-200-471 | E7: Germany | F7: 02/02/2024 | G7: USB-C Cable | H7: Electronics | I7: 9 | J7: 5.5 | L7: Cash | M7: cancelled
A8: 1061 | B8: James Clark | C8: james.clark37@hotmail.com | D8: 938 026 206 | E8: United Arab Emirates | F8: 2023-02-08 | G8: Sunglasses | H8: Accessories | I8: 6 | J8: 22 | K8: 132 | L8: Debit Card | M8: Shipped
A9: 1060 | B9: Olivia Zaki | C9: olivia.zaki92@gmail.com | D9: (733) 848-421 | E9: Germany | F9: 2023-09-06 | G9: Backpack | H9: Accessories | I9: 2 | J9: 30 | L9: Debit Card | M9: COMPLETED
A10: 1014 | B10: mona allen | C10: mona.allen6@yahoo.com | D10: (769) 367-632 | E10: Egypt | F10: 2024-03-11 | G10: Water Bottle | H10: Kitchenware | I10: 4 | J10: 9 | K10: 36 | L10: Debit Card | M10: Cancelled
A11: 1042 | B11: Ava Taylor | C11: ava.taylor@yahoo.com | D11: (071) 518-203 | E11: USA | F11: 06/19/2024 | G11: Ceramic Mug | H11: Kitchenware | I11: 7 | L11: PayPal | M11: Cancelled
A12: 1049 | B12: John Fathy | C12: john.fathy97@yahoo.com | D12: unknown | E12: saudi arabia | F12: 08-May-23 | G12: Running Shoes | H12: Sportswear | I12: 7 | J12: 45 | K12: 315 | L12: CC | M12: completed
A13: 1085 | B13: Sara Ali | C13: sara.ali@outlook.com | D13: +20 424-154-152 | E13: United Kingdom | F13: 17-Dec-24 | G13: Running Shoes | H13: Sportswear | I13: 1 | J13: 45 | K13: 45 | L13: Credit Card | M13: Cancelled
A14: 1005 | B14: Lucas Allen | C14: lucas.allen@hotmail.com | D14: +20 315-098-393 | E14: UK | F14: 2023-08-23 | G14: Wireless Mouse | H14: Electronics | I14: 4 | J14: 8.5 | K14: 34 | L14: debit card | M14: Shipped
A15: 1040 | B15: sara saad | C15: sara.saad@hotmail.com | D15: 968 164 535 | E15: Egypt | F15: 2024-10-10 | G15: Backpack | H15: accessories | I15: 6 | J15: 30 | L15: Credit_Card | M15: COMPLETED
A16: 1030 | B16: Youssef Farouk | C16: youssef.farouk@gmail.com | D16: (909) 743-953 | E16: germany | F16: 25-Nov-24 | G16: USB-C Cable | H16: Electronics | I16: 2 | J16: 5.5 | K16: 11 | L16: paypal | M16: COMPLETED
A17: 1018 | B17: Mostafa Wilson | C17: mostafa.wilson@hotmail.com | D17: 663 193 149 | E17: Germany | F17: 12/22/2023 | G17: USB-C Cable | H17: Electronics | I17: -6 | J17: 5.5 | K17: -33 | L17: Cash | M17: COMPLETED
A18: 1000 | B18: Laila Hassan | C18: laila.hassan95@gmail.com | E18: GERMANY | F18: 01/28/2023 | G18: Water Bottle | H18: Kitchenware | I18: 4 | J18: 9 | K18: 36 | L18: cash | M18: Cancelled
A19: 1055 | B19: liam rashad | C19: liam.rashad@hotmail.com | D19: +20 815-371-473 | E19: egypt | F19: January 29, 2024 | G19: Running Shoes | H19: Sportswear | I19: 3 | J19: 45 | K19: 135 | L19: Debit Card | M19: Shipped
A20: 1062 | B20: Salma El-Sayed | C20: SALMA.EL-SAYED@YAHOO.COM | D20: (329) 668-516 | E20: U.A.E. | F20: 03/05/2024 | G20: Desk Lamp | H20: furniture | I20: 8 | J20: 15 | L20: PayPal | M20: Cancelled
A21: 1064 | B21: Nour Brown | C21: nour.brown67@outlook.com | D21: (187) 072-867 | E21: germany | F21: 19-Nov-24 | G21: Water Bottle | H21: kitchenware | I21: 1 | L21: Cash | M21: completed
A22: 1020 | B22: Hall, Yasmin | C22: yasmin.hall@outlook.com | D22: 0634957885 | E22: United Kingdom | F22: 27-Dec-23 | G22: Notebook Set | H22: Stationery | I22: 4 | J22: 4 | K22: 16 | L22: paypal | M22: Shipped
A23: 1027 | B23: Grace Taylor | C23: grace.taylor@hotmail.com | D23: (533) 963-605 | E23: uk | F23: January 31, 2024 | G23: USB-C Cable | H23: Electronics | I23: 1 | J23: 5.5 | K23: 5.5 | L23: credit card | M23: shipped
A24: 1041 | B24: Ryan Youssef | C24: ryan.youssef@outlook.com | D24: (995) 527-177 | E24: Saudi Arabia | F24: 12/27/2023 | G24: Notebook Set | H24: Stationery | I24: 6 | J24: 4 | K24: 24 | L24: Debit Card | M24: cancelled
A25: 1004 | B25: Dina Johnson | C25: dina.johnson@yahoo.com | D25: +20 809-570-154 | E25: UAE | F25: 29-Mar-23 | G25: Bluetooth Speaker | H25: Electronics | I25: 3 | J25: 25 | K25: 75 | L25: cash | M25: Pending
A26: 1083 | B26: Ethan Zaki | C26: ethan.zaki@hotmail.com | D26: (126) 042-232 | E26: uae | F26: 2024-05-16 | G26: USB-C Cable | H26: Electronics | I26: 8 | J26: 5.5 | K26: 44 | L26: paypal | M26: Cancelled
A27: 1067 | B27: Ethan Saad | C27: ethan.saad19@yahoo.com | D27: 0926870568 | E27: usa | F27: 02/06/2023 | G27: Office Chair | H27: Furniture | I27: 4 | J27: 90 | K27: 360 | L27: cash | M27: shipped
A28: 1035 | B28: Sara Ibrahim | C28: SARA.IBRAHIM92@OUTLOOK.COM | D28: (124) 998-569 | E28: USA | F28: 11/09/2024 | G28: Water Bottle | H28: kitchenware | I28: 9 | J28: 9 | K28: 81 | L28: Cash | M28: cancelled
A29: 1072 | B29: Mona Nasser | C29: monanasser22@gmail.com | D29: +20 918-033-974 | E29: EG | F29: October 15, 2023 | G29: Sunglasses | H29: Accessories | I29: -6 | J29: 22 | K29: -132 | L29: credit card | M29: pending
A30: 1034 | B30: ryan hassan | C30: ryan.hassan@yahoo.com | D30: (539) 502-402 | E30: Germany | F30: 07/03/2023 | G30: Ceramic Mug | H30: Kitchenware | I30: 9 | J30: 6 | K30: 54 | L30: CC | M30: Shipped
A31: 1092 | B31: AHMED SALEM | C31: ahmed.salem@gmail.com | D31: (413) 836-702 | E31: Egypt | F31: August 26, 2023 | G31: Backpack | H31: Accessories | I31: 8 | J31: 30 | K31: 240 | L31: credit card | M31: Completed
A32: 1037 | B32: Khaled Wilson | D32: (273) 158-514 | E32: USA | F32: 09/28/2024 | G32: USB-C Cable | H32: Electronics | I32: -5 | J32: 5.5 | K32: -27.5 | L32: CREDIT CARD | M32: COMPLETED
A33: 1026 | B33: Ali, Hassan | D33: (748) 467-737 | E33: U.S.A. | F33: 09/05/2024 | G33: Office Chair | H33: Furniture | I33: 7 | J33: $90.0 | L33: paypal | M33: pending
A34: 1048 | B34: david zaki | D34: 0531952058 | E34: U.K. | F34: 02/12/2024 | G34: Water Bottle | H34: Kitchenware | I34: 3 | J34: 9 | L34: Credit_Card | M34: Completed
A35: 1018 | B35: Mostafa Wilson | C35: mostafa.wilson@hotmail.com | D35: 663 193 149 | E35: Germany | F35: 12/22/2023 | G35: USB-C Cable | H35: Electronics | I35: -6 | J35: 5.5 | K35: -33 | L35: Cash | M35: COMPLETED
A36: 1079 | B36: Sara Saad | C36: sara.saad@yahoo.com | D36: (673) 622-660 | E36: uae | F36: 29/08/2024 | G36: Wireless Mouse | H36: Electronics | I36: 2 | J36: 8.5 | K36: 17 | L36: credit card | M36: pending
A37: 1041 | B37: Ryan Youssef | C37: ryan.youssef@outlook.com | D37: (995) 527-177 | E37: Saudi Arabia | F37: 12/27/2023 | G37: Notebook Set | H37: Stationery | I37: 6 | J37: 4 | K37: 24 | L37: Debit Card | M37: cancelled
A38: 1069 | B38: Chloe Saad | C38: chloe.saad@hotmail.com | D38: (753) 556-093 | E38: egypt | F38: July 20, 2024 | G38: Sunglasses | H38: Accessories | I38: 4 | J38: 22 | K38: 88 | L38: PayPal | M38: Cancelled
A39: 1076 | B39: Zoe Nasser | C39: zoe.nasser@yahoo.com | D39: 0752654793 | E39: Saudi arabia | F39: 2024-01-09 | G39: Sunglasses | H39: accessories | I39: 3 | J39: 22 | K39: 66 | L39: Cash | M39: pending
A40: 1039 | B40: aya ibrahim | C40: ayaibrahim28@yahoo.com | D40: 762 268 388 | E40: Saudi Arabia | F40: February 11, 2024 | G40: Wireless Mouse | H40: Electronics | I40: 2 | J40: 8.5 | K40: 17 | L40: credit card | M40: cancelled
...

Sheet unitPrice
A1: Product | B1: UnitPrice
A2: Yoga Mat | B2: 18
A3: Desk Lamp | B3: 15
A4: Sunglasses | B4: 22
A5: Office Chair | B5: 90
A6: Ceramic Mug | B6: 6
A7: USB-C Cable | B7: 5.5
A8: Backpack | B8: 30
A9: Water Bottle | B9: 9
A10: Running Shoes | B10: 45
A11: Wireless Mouse | B11: 8.5
A12: Notebook Set | B12: 4
A13: Bluetooth Speaker | B13: 25

Sheet Cleaned
D1: OrderID | E1: CustomerName | F1: Email | G1: Phone | H1: Country | I1: OrderDate | J1: Product | K1: Category | L1: Quantity | M1: unitPrice | N1: TotalPrice | O1: PaymentMethod | P1: Status
D2: 1052 | E2: Daniel Mahmoud | F2: daniel.mahmoud@gmail.com | G2: 225 831 323 | H2: Egypt | I2: 45494 | J2: Yoga Mat | K2: Sportswear | L2: 10 | M2: 18 | N2: 180 | O2: Cash | P2: Cancelled
D3: 1058 | E3: Noah Johnson | F3: noah.johnson@hotmail.com | G3: (409) 749-930 | H3: United Arab Emirates | I3: 45078 | J3: Desk Lamp | K3: Furniture | L3: 2 | M3: 15 | N3: 30 | O3: Debit Card | P3: Shipped
D4: 1023 | E4: Daniel Walker | F4: daniel.walker@outlook.com | G4: +20 936-183-242 | H4: United Arab Emirates | I4: 45536 | J4: Sunglasses | K4: Accessories | L4: 8 | M4: 22 | N4: 176 | O4: Credit Card | P4: Completed
D5: 1061 | E5: James Clark | F5: james.clark37@hotmail.com | G5: 938 026 206 | H5: United Arab Emirates | I5: 44965 | J5: Sunglasses | K5: Accessories | L5: 6 | M5: 22 | N5: 132 | O5: Debit Card | P5: Shipped
D6: 1019 | E6: Emma Abdallah | F6: emma.abdallah@outlook.com | G6: (531) 473-799 | H6: Saudi Arabia | I6: 45433 | J6: Office Chair | K6: Furniture | L6: 5 | M6: 90 | N6: 450 | O6: Credit Card | P6: Completed
D7: 1044 | E7: Mia El-Sayed | F7: miael-sayed@gmail.com | G7: +20 805-929-622 | H7: United Kingdom | I7: 45375 | J7: Ceramic Mug | K7: Kitchenware | L7: 8 | M7: 6 | N7: 48 | O7: Cash | P7: Pending
D8: 1042 | E8: Ava Taylor | F8: ava.taylor@yahoo.com | G8: (071) 518-203 | H8: United States | I8: 45462 | J8: Ceramic Mug | K8: Kitchenware | L8: 7 | M8: 6 | N8: 42 | O8: PayPal | P8: Cancelled
D9: 1032 | E9: Hassan Smith | F9: hassan.smith@yahoo.com | G9: +20 461-200-471 | H9: Germany | I9: 45324 | J9: USB-C Cable | K9: Electronics | L9: 9 | M9: 5.5 | N9: 49.5 | O9: Cash | P9: Cancelled
D10: 1060 | E10: Olivia Zaki | F10: olivia.zaki92@gmail.com | G10: (733) 848-421 | H10: Germany | I10: 45175 | J10: Backpack | K10: Accessories | L10: 2 | M10: 30 | N10: 60 | O10: Debit Card | P10: Completed
D11: 1014 | E11: Mona Allen | F11: mona.allen6@yahoo.com | G11: (769) 367-632 | H11: Egypt | I11: 45362 | J11: Water Bottle | K11: Kitchenware | L11: 4 | M11: 9 | N11: 36 | O11: Debit Card | P11: Cancelled
D12: 1049 | E12: John Fathy | F12: john.fathy97@yahoo.com | G12: N/A | H12: Saudi Arabia | I12: 45054 | J12: Running Shoes | K12: Sportswear | L12: 7 | M12: 45 | N12: 315 | O12: Credit Card | P12: Completed
D13: 1085 | E13: Sara Ali | F13: sara.ali@outlook.com | G13: +20 424-154-152 | H13: United Kingdom | I13: 45643 | J13: Running Shoes | K13: Sportswear | L13: 1 | M13: 45 | N13: 45 | O13: Credit Card | P13: Cancelled
... D95: 1091 | E95: Laila Johnson | F95: Unknown | G95: (806) 174-451 | H95: Egypt | I95: 45132 | J95: Notebook Set | K95: Stationery | L95: 6 | M95: 4 | N95: 24 | O95: Credit Card | P95: Completed

Sheet ChartsTables
F3: Country | G3: Max | H3: less | J3: Highest Cancelld Cat | K3: highest | L3: mid | M3: lowest | O3: Highest Cancelled Country | P3: higest | Q3: mid | R3: lowest | T3: Country Sales Cancelled | U3: Net Revenue | V3: Cancelled | Y3: Status_by_Category | Z3: Sum of Quantity
C4: Count of OrderID | D4: Sum of Total Price | E4: Sum orders | F4: =Summary!B4 -> Egypt | G4: =IF(Summary!C4=MAX(Summary!$C$4:$C$9),Summary!C4,NA()) -> 3902 | H4: =IF(Summary!C4<>MAX(Summary!$C$4:$C$9),Summary!C4,NA()) -> #N/A | J4: Accessories | K4: =IF(Q14=MAX(Table16[Completed]),Q14,NA()) -> #N/A | L4: =IF(AND(Q14<>MAX(Table16[Completed]),Q14<>MIN($Q$15:$Q$19)),Q14,NA()) -> 44 | M4: =IF(Q14=MIN(Table16[Completed]),Q14,NA()) -> #N/A | O4: =Summary!I15 -> Egypt | P4: =IF(U4=MAX(Table18[Net Revenue]),U4,NA()) -> #N/A | Q4: =IF(AND(U4<>MAX(Table18[Net Revenue]),U4<>MIN(Table18[Net Revenue])),U4,NA()) -> 61 | R4: =IF(U4=MIN(Table18[Net Revenue]),U4,NA()) -> #N/A | T4: United Kingdom | U4: =IFERROR(GETPIVOTDATA("Quantity", Summary!$I$13, "Status", "Completed", "Country", T4), 0) + IFERROR(GETPIVOTDATA("Quantity", Summary!$I$13, "Status", "Pending", "Country", T4), 0) + IFERROR(GETPIVOTDATA("Quantity", Summary!$I$13, "Status", "Shipped", "Country", T4), 0) -> 61 | V4: =IFERROR(GETPIVOTDATA("Quantity", Summary!$I$13, "Status", "Cancelled", "Country", T4), 0) -> 1 | Y4: Cancelled | Z4: 151
C5: 94 | D5: 11056 | E5: =SUM(Table12[Sum of Quantity]) -> 502 | F5: =Summary!B5 -> Germany | G5: =IF(Summary!C5=MAX(Summary!$C$4:$C$9),Summary!C5,NA()) -> #N/A | H5: =IF(Summary!C5<>MAX(Summary!$C$4:$C$9),Summary!C5,NA()) -> 828.5 | J5: Electronics | K5: =IF(Q15=MAX(Table16[Completed]),Q15,NA()) -> #N/A | L5: =IF(AND(Q15<>MAX(Table16[Completed]),Q15<>MIN($Q$15:$Q$19)),Q15,NA()) -> 32 | M5: =IF(Q15=MIN(Table16[Completed]),Q15,NA()) -> #N/A | O5: =Summary!I16 -> Germany | P5: =IF(U5=MAX(Table18[Net Revenue]),U5,NA()) -> #N/A | Q5: =IF(AND(U5<>MAX(Table18[Net Revenue]),U5<>MIN(Table18[Net Revenue])),U5,NA()) -> 36 | R5: =IF(U5=MIN(Table18[Net Revenue]),U5,NA()) -> #N/A | T5: Saudi Arabia | U5: =IFERROR(GETPIVOTDATA("Quantity", Summary!$I$13, "Status", "Completed", "Country", T5), 0) + IFERROR(GETPIVOTDATA("Quantity", Summary!$I$13, "Status", "Pending", "Country", T5), 0) + IFERROR(GETPIVOTDATA("Quantity", Summary!$I$13, "Status", "Shipped", "Country", T5), 0) -> 36 | V5: =IFERROR(GETPIVOTDATA("Quantity", Summary!$I$13, "Status", "Cancelled", "Country", T5), 0) -> 10 | Y5: Stationery | Z5: 13
F6: =Summary!B6 -> Saudi Arabia | G6: =IF(Summary!C6=MAX(Summary!$C$4:$C$9),Summary!C6,NA()) -> #N/A | H6: =IF(Summary!C6<>MAX(Summary!$C$4:$C$9),Summary!C6,NA()) -> 1623 | J6: Furniture | K6: =IF(Q16=MAX(Table16[Completed]),Q16,NA()) -> #N/A | L6: =IF(AND(Q16<>MAX(Table16[Completed]),Q16<>MIN($Q$15:$Q$19)),Q16,NA()) -> #N/A | M6: =IF(Q16=MIN(Table16[Completed]),Q16,NA()) -> #N/A | O6: =Summary!I17 -> Saudi Arabia | P6: =IF(U6=MAX(Table18[Net Revenue]),U6,NA()) -> #N/A | Q6: =IF(AND(U6<>MAX(Table18[Net Revenue]),U6<>MIN(Table18[Net Revenue])),U6,NA()) -> 59 | R6: =IF(U6=MIN(Table18[Net Revenue]),U6,NA()) -> #N/A | T6: United Arab Emirates | U6: =IFERROR(GETPIVOTDATA("Quantity", Summary!$I$13, "Status", "Completed", "Country", T6), 0) + IFERROR(GETPIVOTDATA("Quantity", Summary!$I$13, "Status", "Pending", "Country", T6), 0) + IFERROR(GETPIVOTDATA("Quantity", Summary!$I$13, "Status", "Shipped", "Country", T6), 0) -> 59 | V6: =IFERROR(GETPIVOTDATA("Quantity", Summary!$I$13, "Status", "Cancelled", "Country", T6), 0) -> 29 | Y6: Sportswear | Z6: 36
F7: =Summary!B7 -> United Arab Emirates | G7: =IF(Summary!C7=MAX(Summary!$C$4:$C$9),Summary!C7,NA()) -> #N/A | H7: =IF(Summary!C7<>MAX(Summary!$C$4:$C$9),Summary!C7,NA()) -> 1896 | J7: Kitchenware | K7: =IF(Q17=MAX(Table16[Completed]),Q17,NA()) -> #N/A | L7: =IF(AND(Q17<>MAX(Table16[Completed]),Q17<>MIN($Q$15:$Q$19)),Q17,NA()) -> #N/A | M7: =IF(Q17=MIN(Table16[Completed]),Q17,NA()) -> #N/A | O7: =Summary!I18 -> United Arab Emirates | P7: =IF(U7=MAX(Table18[Net Revenue]),U7,NA()) -> #N/A | Q7: =IF(AND(U7<>MAX(Table18[Net Revenue]),U7<>MIN(Table18[Net Revenue])),U7,NA()) -> 67 | R7: =IF(U7=MIN(Table18[Net Revenue]),U7,NA()) -> #N/A | T7: United States | U7: =IFERROR(GETPIVOTDATA("Quantity", Summary!$I$13, "Status", "Completed", "Country", T7), 0) + IFERROR(GETPIVOTDATA("Quantity", Summary!$I$13, "Status", "Pending", "Country", T7), 0) + IFERROR(GETPIVOTDATA("Quantity", Summary!$I$13, "Status", "Shipped", "Country", T7), 0) -> 67 | V7: =IFERROR(GETPIVOTDATA("Quantity", Summary!$I$13, "Status", "Cancelled", "Country", T7), 0) -> 30 | Y7: Kitchenware | Z7: 44
C8: Row Labels | D8: Sum of Quantity | F8: =Summary!B8 -> United Kingdom | G8: =IF(Summary!C8=MAX(Summary!$C$4:$C$9),Summary!C8,NA()) -> #N/A | H8: =IF(Summary!C8<>MAX(Summary!$C$4:$C$9),Summary!C8,NA()) -> 1092.5 | J8: Sportware | K8: =IF(Q18=MAX(Table16[Completed]),Q18,NA()) -> #N/A | L8: =IF(AND(Q18<>MAX(Table16[Completed]),Q18<>MIN($Q$15:$Q$19)),Q18,NA()) -> 36 | M8: =IF(Q18=MIN(Table16[Completed]),Q18,NA()) -> #N/A | O8: =Summary!I19 -> United Kingdom | P8: =IF(U8=MAX(Table18[Net Revenue]),U8,NA()) -> 104 | Q8: =IF(AND(U8<>MAX(Table18[Net Revenue]),U8<>MIN(Table18[Net Revenue])),U8,NA()) -> #N/A | R8: =IF(U8=MIN(Table18[Net Revenue]),U8,NA()) -> #N/A | T8: Egypt | U8: =IFERROR(GETPIVOTDATA("Quantity", Summary!$I$13, "Status", "Completed", "Country", T8), 0) + IFERROR(GETPIVOTDATA("Quantity", Summary!$I$13, "Status", "Pending", "Country", T8), 0) + IFERROR(GETPIVOTDATA("Quantity", Summary!$I$13, "Status", "Shipped", "Country", T8), 0) -> 104 | V8: =IFERROR(GETPIVOTDATA("Quantity", Summary!$I$13, "Status", "Cancelled", "Country", T8), 0) -> 36 | Y8: Furniture | Z8: 13
C9: Cancelled | D9: 151 | F9: =Summary!B9 -> United States | G9: =IF(Summary!C9=MAX(Summary!$C$4:$C$9),Summary!C9,NA()) -> #N/A | H9: =IF(Summary!C9<>MAX(Summary!$C$4:$C$9),Summary!C9,NA()) -> 1714 | J9: Stationery | K9: =IF(Q19=MAX(Table16[Completed]),Q19,NA()) -> #N/A | L9: =IF(AND(Q19<>MAX(Table16[Completed]),Q19<>MIN($Q$15:$Q$19)),Q19,NA()) -> #N/A | M9: =IF(Q19=MIN(Table16[Completed]),Q19,NA()) -> #N/A | O9: =Summary!I20 -> United States | P9: =IF(U9=MAX(Table18[Net Revenue]),U9,NA()) -> #N/A | Q9: =IF(AND(U9<>MAX(Table18[Net Revenue]),U9<>MIN(Table18[Net Revenue])),U9,NA()) -> #N/A | R9: =IF(U9=MIN(Table18[Net Revenue]),U9,NA()) -> 24 | T9: Germany | U9: =IFERROR(GETPIVOTDATA("Quantity", Summary!$I$13, "Status", "Completed", "Country", T9), 0) + IFERROR(GETPIVOTDATA("Quantity", Summary!$I$13, "Status", "Pending", "Country", T9), 0) + IFERROR(GETPIVOTDATA("Quantity", Summary!$I$13, "Status", "Shipped", "Country", T9), 0) -> 24 | V9: =IFERROR(GETPIVOTDATA("Quantity", Summary!$I$13, "Status", "Cancelled", "Country", T9), 0) -> 45 | Y9: Electronics | Z9: 32
C10: Completed | D10: 185 | Y10: Accessories | Z10: 13
C11: Pending | D11: 62 | J11: Highest Completed Cat | K11: highest | L11: reset | Y11: Completed | Z11: 185
C12: Shipped | D12: 104 | J12: =Summary!E22 -> Stationery | K12: =IF(P22=MAX(#REF!),P22,NA()) -> #REF! | L12: =IF(P22<>MAX(#REF!),P22,NA()) -> #REF! | Y12: Pending | Z12: 62
F13: Row Labels | G13: Sum of TotalPrice | J13: =Summary!E23 -> Sportswear | K13: =IF(P23=MAX(#REF!),P23,NA()) -> #REF! | L13: =IF(P23<>MAX(#REF!),P23,NA()) -> #REF! | O13: Sales by Category | P13: Completed | Q13: Cancelled | Y13: Shipped | Z13: 104
F14: Cash | G14: 4125.5 | J14: =Summary!E24 -> Kitchenware | K14: =IF(P24=MAX(#REF!),P24,NA()) -> #REF! | L14: =IF(P24<>MAX(#REF!),P24,NA()) -> #REF! | O14: Kitchenware | P14: =IFERROR(GETPIVOTDATA("Quantity",Summary!$E$13, "Status", "Completed", "Category", Table16[[#This Row],[Sales by Category]]), 0) -> 47 | Q14: =IFERROR(GETPIVOTDATA("Quantity",Summary!$E$13, "Status", "Cancelled", "Category", O14), 0) -> 44 | Y14: Grand Total | Z14: 502
F15: Credit Card | G15: 3120 | J15: =Summary!E25 -> Furniture | K15: =IF(P25=MAX(#REF!),P25,NA()) -> #REF! | L15: =IF(P25<>MAX(#REF!),P25,NA()) -> #REF! | O15: Electronics | P15: =IFERROR(GETPIVOTDATA("Quantity",Summary!$E$13, "Status", "Completed", "Category", Table16[[#This Row],[Sales by Category]]), 0) -> 36 | Q15: =IFERROR(GETPIVOTDATA("Quantity",Summary!$E$13, "Status", "Cancelled", "Category", O15), 0) -> 32
F16: Debit Card | G16: 975.5 | J16: =Summary!E26 -> Electronics | K16: =IF(P26=MAX(#REF!),P26,NA()) -> #REF! | L16: =IF(P26<>MAX(#REF!),P26,NA()) -> #REF! | O16: Furniture | P16: =IFERROR(GETPIVOTDATA("Quantity",Summary!$E$13, "Status", "Completed", "Category", Table16[[#This Row],[Sales by Category]]), 0) -> 32 | Q16: =IFERROR(GETPIVOTDATA("Quantity",Summary!$E$13, "Status", "Cancelled", "Category", O16), 0) -> 13
F17: PayPal | G17: 2835 | J17: =Summary!E27 -> Accessories | K17: =IF(P27=MAX(#REF!),P27,NA()) -> #REF! | L17: =IF(P27<>MAX(#REF!),P27,NA()) -> #REF! | O17: Accessories | P17: =IFERROR(GETPIVOTDATA("Quantity",Summary!$E$13, "Status", "Completed", "Category", Table16[[#This Row],[Sales by Category]]), 0) -> 30 | Q17: =IFERROR(GETPIVOTDATA("Quantity",Summary!$E$13, "Status", "Cancelled", "Category", O17), 0) -> 13
O18: Sportswear | P18: =IFERROR(GETPIVOTDATA("Quantity",Summary!$E$13, "Status", "Completed", "Category", Table16[[#This Row],[Sales by Category]]), 0) -> 20 | Q18: =IFERROR(GETPIVOTDATA("Quantity",Summary!$E$13, "Status", "Cancelled", "Category", O18), 0) -> 36
D19: 9105 | O19: Stationery | P19: =IFERROR(GETPIVOTDATA("Quantity",Summary!$E$13, "Status", "Completed", "Category", Table16[[#This Row],[Sales by Category]]), 0) -> 20 | Q19: =IFERROR(GETPIVOTDATA("Quantity",Summary!$E$13, "Status", "Cancelled", "Category", O19), 0) -> 13
D20: 68

Sheet Summary
B3: Country | C3: Total Revenue | E3: Category | F3: Total Revenue | H3: Status | I3: Sum of Quantity | K3: Category | L3: Sum of Quantity | N3: CustomerName | O3: % of Total | Q3: PaymentMethod | R3: Sum of TotalPrice
B4: Egypt | C4: 3902 | E4: Accessories | F4: 2040 | H4: Cancelled | I4: 151 | K4: Stationery | L4: 39 | N4: Ahmed Brown | O4: 0.0032561505 | Q4: Cash | R4: 4125.5
B5: Germany | C5: 828.5 | E5: Electronics | F5: 1084 | H5: Completed | I5: 185 | K5: Sportswear | L5: 67 | N5: Ahmed Salem | O5: 0.02170767 | Q5: Credit Card | R5: 3120
B6: Saudi Arabia | C6: 1623 | E6: Furniture | F6: 5190 | H6: Pending | I6: 62 | K6: Kitchenware | L6: 115 | N6: Ali Hassan | O6: 0.056982634 | Q6: Debit Card | R6: 975.5
B7: United Arab Emirates | C7: 1896 | E7: Kitchenware | F7: 813 | H7: Shipped | I7: 104 | K7: Furniture | L7: 111 | N7: Amr Allen | O7: 0.006512301 | Q7: PayPal | R7: 2835
B8: United Kingdom | C8: 1092.5 | E8: Sportswear | F8: 1773 | H8: Grand Total | I8: 502 | K8: Electronics | L8: 94 | N8: Ava Hassan | O8: 0.0081403763 | Q8: Grand Total | R8: 11056
B9: United States | C9: 1714 | E9: Stationery | F9: 156 | K9: Accessories | L9: 76 | N9: Ava Mahmoud | O9: 0.0030752533
B10: Grand Total | C10: 11056 | E10: Grand Total | F10: 11056 | K10: Grand Total | L10: 502 | N10: Ava Smith | O10: 0.048842258
N11: Ava Taylor | O11: 0.0037988423
B12: Status | C12: (All) | N12: Ava Wilson | O12: 0
E13: Status_by_Category | F13: Sum of Quantity | I13: Status_by_country | J13: Sum of Quantity | N13: Aya Ibrahim | O13: 0.0015376266
B14: Total Revenue | E14: Cancelled | F14: 151 | I14: Cancelled | J14: 151 | N14: Aya Rashad | O14: 0.0061505065
B15: 11056 | E15: Stationery | F15: 13 | I15: Egypt | J15: 36 | N15: Chloe Ali | O15: 0.012210564
E16: Sportswear | F16: 36 | I16: Germany | J16: 45 | N16: Chloe Saad | O16: 0.007959479
E17: Kitchenware | F17: 44 | I17: Saudi Arabia | J17: 10 | N17: Clark Mona | O17: 0.0040701881
E18: Furniture | F18: 13 | I18: United Arab Emirates | J18: 29 | N18: Daniel Mahmoud | O18: 0.016280753
E19: Electronics | F19: 32 | I19: United Kingdom | J19: 1 | N19: Daniel Walker | O19: 0.015918958
E20: Accessories | F20: 13 | I20: United States | J20: 30 | N20: Daniel Wilson | O20: 0.018994211
E21: Completed | F21: 185 | I21: Completed | J21: 185 | N21: David Allen | O21: 0.0032561505
E22: Stationery | F22: 20 | I22: Egypt | J22: 55 | N22: David Mahmoud | O22: 0.073263386
E23: Sportswear | F23: 20 | I23: Germany | J23: 15 | N23: David Zaki | O23: 0.0024421129
E24: Kitchenware | F24: 47 | I24: Saudi Arabia | J24: 24 | N24: Dina Johnson | O24: 0.0067836469
E25: Furniture | F25: 32 | I25: United Arab Emirates | J25: 33 | N25: Emily Hassan | O25: 0.010853835
E26: Electronics | F26: 36 | I26: United Kingdom | J26: 21 | N26: Emma Abdallah | O26: 0.040701881
E27: Accessories | F27: 30 | I27: United States | J27: 37 | N27: Emma Hall | O27: 0.0016280753
... E41: Accessories | F41: 20 | I41: Grand Total | J41: 502 | N41: James Hall | O41: 0.0054269175
E42: Grand Total | F42: 502 | N42: John Fathy | O42: 0.028491317
N43: Khaled Wilson | O43: 0.0024873372
C44: Status | D44: (All) | N44: Khaled Youssef | O44: 0.010853835
N45: Laila Hassan | O45: 0.0032561505
C46: Sum of Quantity | D46: Column Labels | N46: Laila Johnson | O46: 0.002170767
C47: Country\ Category | D47: Stationery | E47: Sportswear | F47: Kitchenware | G47: Furniture | H47: Electronics | I47: Accessories | J47: Grand Total | N47: Laila Salem | O47: 0.0032561505
C48: Egypt | D48: 10 | E48: 31 | F48: 29 | G48: 38 | I48: 32 | J48: 140 | N48: Lewis Ethan | O48: 0.006512301
C49: Germany | E49: 16 | F49: 22 | G49: 6 | H49: 23 | I49: 2 | J49: 69 | N49: Liam Allen | O49: 0.016280753
C50: Saudi Arabia | D50: 6 | E50: 7 | F50: 5 | G50: 16 | H50: 6 | I50: 6 | J50: 46 | N50: Liam Rashad | O50: 0.012210564
C51: United Arab Emirates | E51: 2 | F51: 12 | G51: 14 | H51: 28 | I51: 32 | J51: 88 | N51: Lucas Allen | O51: 0.0030752533
C52: United Kingdom | D52: 6 | E52: 11 | F52: 15 | G52: 19 | H52: 11 | J52: 62 | N52: Lucas Ibrahim | O52: 0.0029848046
C53: United States | D53: 17 | F53: 32 | G53: 18 | H53: 26 | I53: 4 | J53: 97 | N53: Mahmoud Emma | O53: 0.0016280753
C54: Grand Total | D54: 39 | E54: 67 | F54: 115 | G54: 111 | H54: 94 | I54: 76 | J54: 502 | N54: Mia El-Sayed | O54: 0.004341534
N55: Mia Fathy | O55: 0.013567294
...

Sheet charts

Sheet KPIs
E3: Total Sales | F3: Highest Country buying | G3: Most Cat | H3: AOV | I3: Total revenue for the top category | J3: Cancellation rate for the top category | L3: Total revenue for the top Country
E4: =GETPIVOTDATA("TotalPrice",Summary!$B$14) -> 11056 | F4: {=_xlfn.LET( _xlpm.data,_xlfn._xlws.FILTER(Summary!B4:C10,(Summary!B4:B10<>"")*(Summary!B4:B10<>"Grand Total")), _xlfn.TAKE(_xlfn.SORTBY(_xlpm.data,_xlfn.CHOOSECOLS(_xlpm.data,2),-1),1,1) )} -> Egypt | G4: {=_xlfn.LET( _xlpm.data,_xlfn._xlws.FILTER(Summary!E4:F10,(Summary!E4:E10<>"")*(Summary!E4:E10<>"Grand Total")), _xlfn.TAKE(_xlfn.SORTBY(_xlpm.data,_xlfn.CHOOSECOLS(_xlpm.data,2),-1),1,1) )} -> Furniture | H4: =GETPIVOTDATA("TotalPrice",ChartsTables!$D$4)/GETPIVOTDATA("OrderID",ChartsTables!$C$4) -> 117.61702 | I4: =GETPIVOTDATA("Total Revenue", Summary!$E$3, "Category", KPIs!G4) -> 5190 | J4: =COUNTIFS(Cleaning[Status],"Cancelled",Cleaning[Category],KPIs!G4) /COUNTIFS(Cleaning[Category],KPIs!G4) -> 0.15789474 | L4: =GETPIVOTDATA("Total Revenue", Summary!B3, "Country", KPIs!F4) -> 3902

Sheet DashBoard

Sheet ReadMe
A1: About this dataset
A3: This is a deliberately messy 100-row orders dataset for practicing data
A4: preprocessing / cleaning in Power Query (Excel).
A6: It contains realistic data quality issues on purpose, including:
A7: - Inconsistent text casing (UPPER/lower/Mixed) in names, country, category, status, payment method
A8: - Leading/trailing whitespace in several text columns
A9: - Inconsistent country naming (e.g. Egypt / EGYPT / EG / United States / USA)
A10: - Inconsistent date formats across rows (ISO, DD/MM/YYYY, MM/DD/YYYY, 'D-Mon-YY', full text date)
A11: - Missing values (blank Email, Phone, Quantity, UnitPrice, TotalAmount)
A12: - Placeholder text for missing values ('N/A', 'unknown') instead of true blanks
A13: - Inconsistent phone number formats
A14: - A numeric column stored partly as text (UnitPrice sometimes has a '$' prefix)
... A21: task list in the accompanying Word document (Power_Query_Preprocessing_Exercise.docx).
